The error handling in `requestOperation` is designed to ensure that the `after` hook, provided by the `Hooks` interface, is *always* executed, even if the `operateGlobalSynced` method throws an exception.  This is important because the `after` hook might be responsible for releasing resources, logging errors, or performing other cleanup tasks crucial to maintaining system consistency. The nested `try-catch` structure ensures that even if an exception occurs within the `after` hook itself, it's logged without preventing the lock from being released in the `finally` block, preventing a deadlock.

However, there are potential issues. The error handling only logs the exception within the `after` hook; it doesn't re-throw it or propagate it to the caller of `requestOperation`. This means the calling code might not be aware that the `after` hook failed. Also, if the `operateGlobalSynced` operation throws an exception, that exception is effectively swallowed â€“ the calling code receives no indication of the failure. A more robust approach might involve re-throwing the original exception (or wrapping it in a custom exception) after logging the `after` hook failure, allowing the caller to handle the error appropriately.  Additionally, the logging only uses `log.error`. Adding context to the logs (e.g., a unique operation ID) could aid in debugging.